<?xml version="1.0" ?>
<!-- =================================================================================== -->
<!-- |    This document was autogenerated by xacro from jomegatron.urdf.xacro          | -->
<!-- |    EDITING THIS FILE BY HAND IS NOT RECOMMENDED                                 | -->
<!-- =================================================================================== -->
<robot name="jomegatron" xmlns:controller="http://playerstage.sourceforge.net/gazebo/xmlschema/#controller" xmlns:interface="http://playerstage.sourceforge.net/gazebo/xmlschema/#interface" xmlns:sensor="http://playerstage.sourceforge.net/gazebo/xmlschema/#sensor">
  <!-- all values are in inches and are converted to meters bellow -->
  <material name="Green">
    <color rgba="0.0 0.8 0.0 1.0"/>
  </material>
  <material name="Black">
    <color rgba="0 0 0 1"/>
  </material>
  <material name="Grey">
    <color rgba="0.5 0.5 0.5 1"/>
  </material>
  <material name="Shadow">
    <color rgba="0.25 0.25 0.25 1"/>
  </material>
  <!-- robot footprint -->
  <link name="base_footprint">
    <inertial>
      <mass value="0.0001"/>
      <origin xyz="0 0 0"/>
      <inertia ixx="0.0001" ixy="0.0" ixz="0.0" iyy="0.0001" iyz="0.0" izz="0.0001"/>
    </inertial>
    <visual>
      <origin rpy="0 0 0" xyz="0.254 0 0"/>
      <geometry>
        <box size="1.016 0.7112 0.001"/>
      </geometry>
      <material name="Shadow"/>
    </visual>
    <collision>
      <origin rpy="0 0 0" xyz="0.254 0 0"/>
      <geometry>
        <box size="1.016 0.7112 0.001"/>
      </geometry>
    </collision>
  </link>
  <!-- robot base -->
  <link name="base_link">
    <inertial>
      <mass value="50"/>
      <origin xyz="0 0 0.0"/>
      <inertia ixx="0.01" ixy="0.0" ixz="0.0" iyy="0.01" iyz="0.0" izz="0.5"/>
    </inertial>
    <visual>
      <origin rpy="0 0 0" xyz="0.254 0 0.3048"/>
      <geometry>
        <box size="1.016 0.7112 0.6096"/>
      </geometry>
      <material name="Green"/>
    </visual>
    <collision>
      <origin rpy="0 0 0" xyz="0.254 0 0.3048"/>
      <geometry>
        <box size="1.016 0.7112 0.6096"/>
      </geometry>
    </collision>
  </link>
  <joint name="base_footprint_joint" type="fixed">
    <origin rpy="0 0 0" xyz="0 0 0.2413"/>
    <parent link="base_footprint"/>
    <child link="base_link"/>
  </joint>
  <!-- left wheel -->
  <link name="left_wheel_link">
    <inertial>
      <origin xyz="0 0 0"/>
      <mass value="2"/>
      <inertia ixx="0.001" ixy="0.0" ixz="0.0" iyy="0.001" iyz="0.0" izz="0.001"/>
    </inertial>
    <visual>
      <origin rpy="0 1.57075 1.57075" xyz="0 0 0"/>
      <geometry>
        <cylinder length="0.127" radius="0.2032"/>
      </geometry>
      <material name="Black"/>
    </visual>
    <collision>
      <origin rpy="0 1.57075 1.57075" xyz="0 0 0"/>
      <geometry>
        <cylinder length="0.127" radius="0.2032"/>
      </geometry>
    </collision>
  </link>
  <joint name="left_wheel_joint" type="continuous">
    <origin rpy="0 0 0" xyz="0 -0.2667 -0.0381 "/>
    <parent link="base_link"/>
    <child link="left_wheel_link"/>
    <axis xyz="0 1 0"/>
  </joint>
  <!-- right wheel -->
  <link name="right_wheel_link">
    <inertial>
      <origin xyz="0 0 0"/>
      <mass value="2"/>
      <inertia ixx="0.001" ixy="0.0" ixz="0.0" iyy="0.001" iyz="0.0" izz="0.001"/>
    </inertial>
    <visual>
      <origin rpy="0 1.57075 1.57075" xyz="0 0 0"/>
      <geometry>
        <cylinder length="0.127" radius="0.2032"/>
      </geometry>
      <material name="Black"/>
    </visual>
    <collision>
      <origin rpy="0 1.57075 1.57075" xyz="0 0 0"/>
      <geometry>
        <cylinder length="0.127" radius="0.2032"/>
      </geometry>
    </collision>
  </link>
  <joint name="right_wheel_joint" type="continuous">
    <origin rpy="0 0 0" xyz="0 0.2667 -0.0381 "/>
    <parent link="base_link"/>
    <child link="right_wheel_link"/>
    <axis xyz="0 1 0"/>
  </joint>
  <!-- right castor bar -->
  <link name="right_castor_bar_link">
    <inertial>
      <origin xyz="0 0 0"/>
      <mass value=".5"/>
      <inertia ixx="0.001" ixy="0.0" ixz="0.0" iyy="0.001" iyz="0.0" izz="0.001"/>
    </inertial>
    <visual>
      <origin rpy="0 0 0" xyz="0 0 -0.0762"/>
      <geometry>
        <box size="0.127 0.1016 0.1524"/>
      </geometry>
      <material name="Grey"/>
    </visual>
    <collision>
      <origin rpy="0 0 0" xyz="0 0 0.0762"/>
      <geometry>
        <box size="0.127 0.1016 0.1524"/>
      </geometry>
    </collision>
  </link>
  <joint name="right_castor_bar_joint" type="fixed">
    <origin rpy="0 0 0" xyz="0.635 0.2667 0"/>
    <parent link="base_link"/>
    <child link="right_castor_bar_link"/>
    <axis xyz="0 0 1"/>
  </joint>
  <!-- left castor bar -->
  <link name="left_castor_bar_link">
    <inertial>
      <origin xyz="0 0 0"/>
      <mass value=".5"/>
      <inertia ixx="0.001" ixy="0.0" ixz="0.0" iyy="0.001" iyz="0.0" izz="0.001"/>
    </inertial>
    <visual>
      <origin rpy="0 0 0" xyz="0 0 -0.0762"/>
      <geometry>
        <box size="0.127 0.1016 0.1524"/>
      </geometry>
      <material name="Grey"/>
    </visual>
    <collision>
      <origin rpy="0 0 0" xyz="0 0 0.0762"/>
      <geometry>
        <box size="0.127 0.1016 0.1524"/>
      </geometry>
    </collision>
  </link>
  <joint name="left_castor_bar_joint" type="fixed">
    <origin rpy="0 0 0" xyz="0.635 -0.2667 0"/>
    <parent link="base_link"/>
    <child link="left_castor_bar_link"/>
    <axis xyz="0 0 1"/>
  </joint>
  <!-- right castor -->
  <link name="right_castor_link">
    <inertial>
      <origin xyz="0 0 0"/>
      <mass value="2"/>
      <inertia ixx="0.001" ixy="0.0" ixz="0.0" iyy="0.001" iyz="0.0" izz="0.001"/>
    </inertial>
    <visual>
      <origin rpy="0 1.57075 1.57075" xyz="0 0 0"/>
      <geometry>
        <cylinder length="0.0762" radius="0.1016"/>
      </geometry>
      <material name="Black"/>
    </visual>
    <collision>
      <origin rpy="0 1.57075 1.57075" xyz="0 0 0"/>
      <geometry>
        <cylinder length="0.0762" radius="0.1016"/>
      </geometry>
    </collision>
  </link>
  <joint name="right_castor_joint" type="fixed">
    <origin rpy="0 0 0" xyz="0 0 -0.1397 "/>
    <parent link="right_castor_bar_link"/>
    <child link="right_castor_link"/>
    <axis xyz="0 1 0"/>
  </joint>
  <!-- left castor -->
  <link name="left_castor_link">
    <inertial>
      <origin xyz="0 0 0"/>
      <mass value="2"/>
      <inertia ixx="0.001" ixy="0.0" ixz="0.0" iyy="0.001" iyz="0.0" izz="0.001"/>
    </inertial>
    <visual>
      <origin rpy="0 1.57075 1.57075" xyz="0 0 0"/>
      <geometry>
        <cylinder length="0.0762" radius="0.1016"/>
      </geometry>
      <material name="Black"/>
    </visual>
    <collision>
      <origin rpy="0 1.57075 1.57075" xyz="0 0 0"/>
      <geometry>
        <cylinder length="0.0762" radius="0.1016"/>
      </geometry>
    </collision>
  </link>
  <joint name="left_castor_joint" type="fixed">
    <origin rpy="0 0 0" xyz="0 0 -0.1397 "/>
    <parent link="left_castor_bar_link"/>
    <child link="left_castor_link"/>
    <axis xyz="0 1 0"/>
  </joint>
  <!-- mast base -->
  <link name="mast_base_link">
    <inertial>
      <origin xyz="0 0 0"/>
      <mass value=".5"/>
      <inertia ixx="0.001" ixy="0.0" ixz="0.0" iyy="0.001" iyz="0.0" izz="0.001"/>
    </inertial>
    <visual>
      <origin rpy="0 0 0" xyz="0 0 0.2032"/>
      <geometry>
        <box size="0.0254 0.7112 0.4064"/>
      </geometry>
      <material name="Grey"/>
    </visual>
    <collision>
      <origin rpy="0 0 0" xyz="0.2032 0 0"/>
      <geometry>
        <box size="0.0254 0.7112 0.4064"/>
      </geometry>
    </collision>
  </link>
  <joint name="mast_base_joint" type="fixed">
    <origin rpy="0 0 0" xyz="0.3302 0 0.6096"/>
    <parent link="base_link"/>
    <child link="mast_base_link"/>
    <axis xyz="0 1 0"/>
  </joint>
  <!-- mast vertical -->
  <link name="mast_vertical_link">
    <inertial>
      <origin xyz="0 0 0"/>
      <mass value=".5"/>
      <inertia ixx="0.001" ixy="0.0" ixz="0.0" iyy="0.001" iyz="0.0" izz="0.001"/>
    </inertial>
    <visual>
      <origin rpy="0 0 0" xyz="0 0 0.0635"/>
      <geometry>
        <box size="0.0254 0.0254 0.127"/>
      </geometry>
      <material name="Grey"/>
    </visual>
    <collision>
      <origin rpy="0 0 0" xyz="0 0 0.0635"/>
      <geometry>
        <box size="0.0254 0.0254 0.127"/>
      </geometry>
    </collision>
  </link>
  <joint name="mast_vertical_joint" type="fixed">
    <origin rpy="0 0 0" xyz="0 0 0.4064"/>
    <parent link="mast_base_link"/>
    <child link="mast_vertical_link"/>
    <axis xyz="0 0 1"/>
  </joint>
  <!-- mast horizontal -->
  <link name="mast_horizontal_link">
    <inertial>
      <origin xyz="0 0 0"/>
      <mass value=".5"/>
      <inertia ixx="0.001" ixy="0.0" ixz="0.0" iyy="0.001" iyz="0.0" izz="0.001"/>
    </inertial>
    <visual>
      <origin rpy="0 0 0" xyz="-0.0508 0 0.0127"/>
      <geometry>
        <box size="0.3048 0.0254 0.0254"/>
      </geometry>
      <material name="Grey"/>
    </visual>
    <collision>
      <origin rpy="0 0 0" xyz="-0.0508 0 0.0127"/>
      <geometry>
        <box size="0.3048 0.0254 0.0254"/>
      </geometry>
    </collision>
  </link>
  <joint name="mast_horizontal_joint" type="fixed">
    <origin rpy="0 0 0" xyz="0 0 0.127"/>
    <parent link="mast_vertical_link"/>
    <child link="mast_horizontal_link"/>
    <axis xyz="0 0 1"/>
  </joint>
</robot>

